load model...
/home/wangy/anaconda3/lib/python3.6/site-packages/tensorflow/python/ops/gradients_impl.py:98: UserWarning: Converting sparse IndexedSlices to a dense Tensor of unknown shape. This may consume a large amount of memory.
  "Converting sparse IndexedSlices to a dense Tensor of unknown shape. "
gen  [0.37865497076023447, 0.33903508771929775, 0.28026315789473655, 0.3957953309246699, 0.36963886275152436, 0.33868830652289106]
dis  [0.013157894736842101, 0.01228070175438597, 0.01228070175438596, 0.012667744442533317, 0.012206452377516039, 0.012351830200792559]
multiprocessing.pool.RemoteTraceback: 
"""
Traceback (most recent call last):
  File "/home/wangy/anaconda3/lib/python3.6/multiprocessing/pool.py", line 119, in worker
    result = (True, func(*args, **kwds))
  File "/home/wangy/anaconda3/lib/python3.6/multiprocessing/pool.py", line 44, in mapstar
    return list(map(*args))
  File "cf_gan.py", line 88, in simple_test_one_user
    if i in user_pos_test[u]:
KeyError: 445
"""

The above exception was the direct cause of the following exception:

Traceback (most recent call last):
  File "cf_gan.py", line 264, in <module>
    main()
  File "cf_gan.py", line 243, in main
    result_train = simple_train(sess,generator)
  File "cf_gan.py", line 144, in simple_train
    batch_result = pool.map(simple_test_one_user, user_batch_rating_uid)
  File "/home/wangy/anaconda3/lib/python3.6/multiprocessing/pool.py", line 266, in map
    return self._map_async(func, iterable, mapstar, chunksize).get()
  File "/home/wangy/anaconda3/lib/python3.6/multiprocessing/pool.py", line 644, in get
    raise self._value
KeyError: 445
